<sdf version='1.9'>
  <model name='M20'>
    <!-- Enable collision with other objects, disable self-collision -->
    <self_collide>false</self_collide>
    
    <link name='base_link'>
      <inertial>
        <pose>0.00355105878308153 0.0016507579200937 -0.00346462146571654 0 0 0</pose>
        <mass>15.882</mass>
        <inertia>
          <ixx>0.088078699999999996</ixx>
          <ixy>0.0013960000000000001</ixy>
          <ixz>0.000111</ixz>
          <iyy>0.53381599999999996</iyy>
          <iyz>0.00051900000000000004</iyz>
          <izz>0.56391500000000006</izz>
        </inertia>
      </inertial>
      <collision name='base_link_collision'>
        <pose>0 0 0 0 0 0</pose>
        <geometry>
          <box>
            <size>0.75 0.09 0.14</size>
          </box>
        </geometry>
        <surface>
          <friction>
            <ode>
              <mu>0.8</mu>
              <mu2>0.8</mu2>
            </ode>
          </friction>
          <contact>
            <ode>
              <kp>1e6</kp>
              <kd>100</kd>
              <min_depth>0.001</min_depth>
            </ode>
          </contact>
        </surface>
      </collision>
      <collision name='base_link_collision_1'>
        <pose>0 0.045 0 0 1.570796326794897 0</pose>
        <geometry>
          <cylinder>
            <length>0.75</length>
            <radius>0.070000000000000007</radius>
          </cylinder>
        </geometry>
        <surface>
          <friction>
            <ode>
              <mu>0.8</mu>
              <mu2>0.8</mu2>
            </ode>
          </friction>
          <contact>
            <ode>
              <kp>1e6</kp>
              <kd>100</kd>
              <min_depth>0.001</min_depth>
            </ode>
          </contact>
        </surface>
      </collision>
      <collision name='base_link_collision_2'>
        <pose>0 -0.045 0 0 1.570796326794897 0</pose>
        <geometry>
          <cylinder>
            <length>0.75</length>
            <radius>0.070000000000000007</radius>
          </cylinder>
        </geometry>
        <surface>
          <friction>
            <ode>
              <mu>0.8</mu>
              <mu2>0.8</mu2>
            </ode>
          </friction>
          <contact>
            <ode>
              <kp>1e6</kp>
              <kd>100</kd>
              <min_depth>0.001</min_depth>
            </ode>
          </contact>
        </surface>
      </collision>
      <visual name='base_link_visual'>
        <pose>0 0 0 0 0 0</pose>
        <geometry>
          <mesh>
            <scale>1 1 1</scale>
            <uri>../meshes/base_link.STL</uri>
          </mesh>
        </geometry>
        <material>
          <diffuse>0.941176 0.941176 0.941176 1</diffuse>
          <ambient>0.941176 0.941176 0.941176 1</ambient>
        </material>
      </visual>
      <!-- IMU Sensor -->
      <sensor name='imu_sensor' type='imu'>
        <pose>0.0632 -0.0268 -0.0435 0 0 0</pose>
        <always_on>true</always_on>
        <update_rate>100</update_rate>
        <visualize>false</visualize>
        <!-- topic auto-generated by Gazebo using spawned model name -->
        <imu>
          <angular_velocity>
            <x>
              <noise type='none'/>
            </x>
            <y>
              <noise type='none'/>
            </y>
            <z>
              <noise type='none'/>
            </z>
          </angular_velocity>
          <linear_acceleration>
            <x>
              <noise type='none'/>
            </x>
            <y>
              <noise type='none'/>
            </y>
            <z>
              <noise type='none'/>
            </z>
          </linear_acceleration>
        </imu>
      </sensor>
      
      <!-- Front Camera Sensor -->
      <sensor name='front_camera' type='camera'>
        <pose>0.37646 0 0.03738 0 0 0</pose>
        <always_on>true</always_on>
        <update_rate>30</update_rate>
        <visualize>true</visualize>
        <!-- topic auto-generated by Gazebo using spawned model name -->
        <camera>
          <horizontal_fov>1.047</horizontal_fov>
          <image>
            <width>640</width>
            <height>480</height>
            <format>R8G8B8</format>
          </image>
          <clip>
            <near>0.1</near>
            <far>100</far>
          </clip>
        </camera>
      </sensor>
      
      <!-- Rear Camera Sensor -->
      <sensor name='rear_camera' type='camera'>
        <pose>-0.37646 0 0.03738 0 0 3.14159</pose>
        <always_on>true</always_on>
        <update_rate>30</update_rate>
        <visualize>true</visualize>
        <!-- topic auto-generated by Gazebo using spawned model name -->
        <camera>
          <horizontal_fov>1.047</horizontal_fov>
          <image>
            <width>640</width>
            <height>480</height>
            <format>R8G8B8</format>
          </image>
          <clip>
            <near>0.1</near>
            <far>100</far>
          </clip>
        </camera>
      </sensor>
      
      <!-- Front LiDAR Sensor -->
      <sensor name='front_lidar' type='gpu_lidar'>
        <pose>0.32028 0 -0.013 0 0 0</pose>
        <always_on>true</always_on>
        <update_rate>10</update_rate>
        <visualize>true</visualize>
        <!-- topic auto-generated by Gazebo using spawned model name -->
        <lidar>
          <scan>
            <horizontal>
              <samples>2048</samples>
              <resolution>1</resolution>
              <min_angle>-1.57</min_angle>
              <max_angle>1.57</max_angle>
            </horizontal>
            <vertical>
              <samples>16</samples>
              <resolution>1</resolution>
              <min_angle>-0.261799</min_angle>
              <max_angle>0.261799</max_angle>
            </vertical>
          </scan>
          <range>
            <min>0.05</min>
            <max>30</max>
            <resolution>0.01</resolution>
          </range>
          <noise>
            <type>none</type>
          </noise>
        </lidar>
      </sensor>
      
      <!-- Rear LiDAR Sensor -->
      <sensor name='rear_lidar' type='gpu_lidar'>
        <pose>-0.32028 0 -0.013 0 0 3.14159</pose>
        <always_on>true</always_on>
        <update_rate>10</update_rate>
        <visualize>true</visualize>
        <!-- topic auto-generated by Gazebo using spawned model name -->
        <lidar>
          <scan>
            <horizontal>
              <samples>640</samples>
              <resolution>1</resolution>
              <min_angle>-1.57</min_angle>
              <max_angle>1.57</max_angle>
            </horizontal>
            <vertical>
              <samples>16</samples>
              <resolution>1</resolution>
              <min_angle>-0.261799</min_angle>
              <max_angle>0.261799</max_angle>
            </vertical>
          </scan>
          <range>
            <min>0.05</min>
            <max>30</max>
            <resolution>0.01</resolution>
          </range>
          <noise>
            <type>none</type>
          </noise>
        </lidar>
      </sensor>
    </link>
    <joint name='fl_hipx_joint' type='revolute'>
      <pose relative_to='base_link'>0.3141 0.06850000000000001 0 0 0 0</pose>
      <parent>base_link</parent>
      <child>fl_hipx</child>
      <axis>
        <xyz>-1 0 0</xyz>
        <limit>
          <lower>-0.61099999999999999</lower>
          <upper>0.436</upper>
          <effort>76.400000000000006</effort>
          <velocity>22.399999999999999</velocity>
        </limit>
        <dynamics>
          <spring_reference>0</spring_reference>
          <spring_stiffness>0</spring_stiffness>
        </dynamics>
      </axis>
    </joint>
    <link name='fl_hipx'>
      <pose relative_to='fl_hipx_joint'>0 0 0 0 0 0</pose>
      <inertial>
        <pose>-0.0111893129496933 0.00891693461032669 0.000405665689861192 0 0 0</pose>
        <mass>0.261359958476582</mass>
        <inertia>
          <ixx>0.00018599999999999999</ixx>
          <ixy>2.5000000000000001e-05</ixy>
          <ixz>-1.2e-05</ixz>
          <iyy>0.00037100000000000002</iyy>
          <iyz>-7.9999999999999996e-06</iyz>
          <izz>0.00028800000000000001</izz>
        </inertia>
      </inertial>
      <collision name='fl_hipx_collision'>
        <pose>0 0.055 0 1.57079632 0 0</pose>
        <geometry>
          <cylinder>
            <length>0.14000000000000001</length>
            <radius>0.048000000000000001</radius>
          </cylinder>
        </geometry>
      </collision>
      <visual name='fl_hipx_visual'>
        <pose>0 0 0 0 0 0</pose>
        <geometry>
          <mesh>
            <scale>1 1 1</scale>
            <uri>../meshes/fl_hipx.STL</uri>
          </mesh>
        </geometry>
        <material>
          <diffuse>0.941176 0.941176 0.941176 1</diffuse>
          <ambient>0.941176 0.941176 0.941176 1</ambient>
        </material>
      </visual>
    </link>
    <joint name='fl_hipy_joint' type='revolute'>
      <pose relative_to='fl_hipx'>0 0 0 0 0 0</pose>
      <parent>fl_hipx</parent>
      <child>fl_hipy</child>
      <axis>
        <xyz>0 -1 0</xyz>
        <limit>
          <lower>-2.5830000000000002</lower>
          <upper>2.286</upper>
          <effort>76.400000000000006</effort>
          <velocity>22.399999999999999</velocity>
        </limit>
        <dynamics>
          <spring_reference>0</spring_reference>
          <spring_stiffness>0</spring_stiffness>
        </dynamics>
      </axis>
    </joint>
    <link name='fl_hipy'>
      <pose relative_to='fl_hipy_joint'>0 0 0 0 0 0</pose>
      <inertial>
        <pose>-0.00199374763010413 0.09843896090458019 -0.130663565833427 0 0 0</pose>
        <mass>2.4929999999999999</mass>
        <inertia>
          <ixx>0.038858999999999998</ixx>
          <ixy>-2.3e-05</ixy>
          <ixz>-3.6999999999999998e-05</ixz>
          <iyy>0.038039999999999997</iyy>
          <iyz>-0.0059849999999999999</iyz>
          <izz>0.0038479999999999999</izz>
        </inertia>
      </inertial>
      <collision name='fl_hipy_collision'>
        <pose>-0.01 0.11 -0.125 0 0 0</pose>
        <geometry>
          <box>
            <size>0.07 0.02 0.25</size>
          </box>
        </geometry>
      </collision>
      <collision name='fl_hipy_collision_1'>
        <pose>0 0.11 -0.25 1.57079632 0 0</pose>
        <geometry>
          <cylinder>
            <length>0.089999999999999997</length>
            <radius>0.050000000000000003</radius>
          </cylinder>
        </geometry>
      </collision>
      <visual name='fl_hipy_visual'>
        <pose>0 0 0 0 0 0</pose>
        <geometry>
          <mesh>
            <scale>1 1 1</scale>
            <uri>../meshes/fl_hipy.STL</uri>
          </mesh>
        </geometry>
        <material>
          <diffuse>0.941176 0.941176 0.941176 1</diffuse>
          <ambient>0.941176 0.941176 0.941176 1</ambient>
        </material>
      </visual>
    </link>
    <joint name='fl_knee_joint' type='revolute'>
      <pose relative_to='fl_hipy'>0 0.0984 -0.25 0 0 0</pose>
      <parent>fl_hipy</parent>
      <child>fl_knee</child>
      <axis>
        <xyz>0 -1 0</xyz>
        <limit>
          <lower>-2.7919999999999998</lower>
          <upper>2.8090000000000002</upper>
          <effort>76.400000000000006</effort>
          <velocity>22.399999999999999</velocity>
        </limit>
        <dynamics>
          <spring_reference>0</spring_reference>
          <spring_stiffness>0</spring_stiffness>
        </dynamics>
      </axis>
    </joint>
    <link name='fl_knee'>
      <pose relative_to='fl_knee_joint'>0 0 0 0 0 0</pose>
      <inertial>
        <pose>0.00341916513259743 0.0026912421076368 -0.181265498605881 0 0 0</pose>
        <mass>1.26</mass>
        <inertia>
          <ixx>0.012936</ixx>
          <ixy>-5.3000000000000001e-05</ixy>
          <ixz>0.00022599999999999999</ixz>
          <iyy>0.013122999999999999</iyy>
          <iyz>-0.001681</iyz>
          <izz>0.0016819999999999999</izz>
        </inertia>
      </inertial>
      <collision name='fl_knee_collision'>
        <pose>0.015 -0.015 -0.125 0 0 0</pose>
        <geometry>
          <box>
            <size>0.06 0.025 0.25</size>
          </box>
        </geometry>
      </collision>
      <collision name='fl_knee_collision_1'>
        <pose>0 0.02 -0.25 1.57079632 0 0</pose>
        <geometry>
          <cylinder>
            <length>0.10000000000000001</length>
            <radius>0.040000000000000001</radius>
          </cylinder>
        </geometry>
      </collision>
      <visual name='fl_knee_visual'>
        <pose>0 0 0 0 0 0</pose>
        <geometry>
          <mesh>
            <scale>1 1 1</scale>
            <uri>../meshes/fl_knee.STL</uri>
          </mesh>
        </geometry>
        <material>
          <diffuse>0.941176 0.941176 0.941176 1</diffuse>
          <ambient>0.941176 0.941176 0.941176 1</ambient>
        </material>
      </visual>
    </link>
    <joint name='fl_wheel_joint' type='revolute'>
      <pose relative_to='fl_knee'>0 0.059676 -0.25 0 0 0</pose>
      <parent>fl_knee</parent>
      <child>fl_wheel</child>
      <axis>
        <xyz>0 -1 0</xyz>
        <limit>
          <effort>21.600000000000001</effort>
          <velocity>79.299999999999997</velocity>
          <lower>-10000000000000000</lower>
          <upper>10000000000000000</upper>
        </limit>
        <dynamics>
          <spring_reference>0</spring_reference>
          <spring_stiffness>0</spring_stiffness>
        </dynamics>
      </axis>
    </joint>
    <link name='fl_wheel'>
      <pose relative_to='fl_wheel_joint'>0 0 0 0 0 0</pose>
      <inertial>
        <pose>-3.11398454355682e-07 0.000279001520740008 5.70329233673394e-07 0 0 0</pose>
        <mass>0.63800000000000001</mass>
        <inertia>
          <ixx>0.0015349999999999999</ixx>
          <ixy>0</ixy>
          <ixz>0</ixz>
          <iyy>0.0028530000000000001</iyy>
          <iyz>0</iyz>
          <izz>0.0015349999999999999</izz>
        </inertia>
      </inertial>
      <collision name='fl_wheel_collision'>
        <pose>0 0 0 1.57079632 0 0</pose>
        <geometry>
          <cylinder>
            <length>0.053999999999999999</length>
            <radius>0.089999999999999997</radius>
          </cylinder>
        </geometry>
        <surface>
          <friction>
            <ode>
              <mu>1.0</mu>
              <mu2>1.0</mu2>
              <fdir1>0 0 1</fdir1>
            </ode>
          </friction>
          <contact>
            <ode>
              <kp>1e6</kp>
              <kd>100</kd>
              <min_depth>0.001</min_depth>
            </ode>
          </contact>
        </surface>
      </collision>
      <visual name='fl_wheel_visual'>
        <pose>0 0 0 0 0 0</pose>
        <geometry>
          <mesh>
            <scale>1 1 1</scale>
            <uri>../meshes/fl_wheel.STL</uri>
          </mesh>
        </geometry>
        <material>
          <diffuse>0.941176 0.941176 0.941176 1</diffuse>
          <ambient>0.941176 0.941176 0.941176 1</ambient>
        </material>
      </visual>
    </link>
    <joint name='fr_hipx_joint' type='revolute'>
      <pose relative_to='base_link'>0.3141 -0.06850000000000001 0 0 0 0</pose>
      <parent>base_link</parent>
      <child>fr_hipx</child>
      <axis>
        <xyz>-1 0 0</xyz>
        <limit>
          <lower>-0.436</lower>
          <upper>0.61099999999999999</upper>
          <effort>76.400000000000006</effort>
          <velocity>22.399999999999999</velocity>
        </limit>
        <dynamics>
          <spring_reference>0</spring_reference>
          <spring_stiffness>0</spring_stiffness>
        </dynamics>
      </axis>
    </joint>
    <link name='fr_hipx'>
      <pose relative_to='fr_hipx_joint'>0 0 0 0 0 0</pose>
      <inertial>
        <pose>-0.0110900940309543 -0.0087503473771439 0.000521421017057358 0 0 0</pose>
        <mass>0.261359958476582</mass>
        <inertia>
          <ixx>0.00018599999999999999</ixx>
          <ixy>-2.5999999999999998e-05</ixy>
          <ixz>-1.2e-05</ixz>
          <iyy>0.00037100000000000002</iyy>
          <iyz>7.9999999999999996e-06</iyz>
          <izz>0.00028800000000000001</izz>
        </inertia>
      </inertial>
      <collision name='fr_hipx_collision'>
        <pose>0 -0.055 0 1.57079632 0 0</pose>
        <geometry>
          <cylinder>
            <length>0.14000000000000001</length>
            <radius>0.048000000000000001</radius>
          </cylinder>
        </geometry>
      </collision>
      <visual name='fr_hipx_visual'>
        <pose>0 0 0 0 0 0</pose>
        <geometry>
          <mesh>
            <scale>1 1 1</scale>
            <uri>../meshes/fr_hipx.STL</uri>
          </mesh>
        </geometry>
        <material>
          <diffuse>0.941176 0.941176 0.941176 1</diffuse>
          <ambient>0.941176 0.941176 0.941176 1</ambient>
        </material>
      </visual>
    </link>
    <joint name='fr_hipy_joint' type='revolute'>
      <pose relative_to='fr_hipx'>0 0 0 0 0 0</pose>
      <parent>fr_hipx</parent>
      <child>fr_hipy</child>
      <axis>
        <xyz>0 -1 0</xyz>
        <limit>
          <lower>-2.5830000000000002</lower>
          <upper>2.286</upper>
          <effort>76.400000000000006</effort>
          <velocity>22.399999999999999</velocity>
        </limit>
        <dynamics>
          <spring_reference>0</spring_reference>
          <spring_stiffness>0</spring_stiffness>
        </dynamics>
      </axis>
    </joint>
    <link name='fr_hipy'>
      <pose relative_to='fr_hipy_joint'>0 0 0 0 0 0</pose>
      <inertial>
        <pose>-0.00229991904853988 -0.0989709441053532 -0.130925037640537 0 0 0</pose>
        <mass>2.4929999999999999</mass>
        <inertia>
          <ixx>0.039276999999999999</ixx>
          <ixy>5.0000000000000004e-06</ixy>
          <ixz>-6.3e-05</ixz>
          <iyy>0.038484999999999998</iyy>
          <iyz>0.0059699999999999996</iyz>
          <izz>0.003921</izz>
        </inertia>
      </inertial>
      <collision name='fr_hipy_collision'>
        <pose>-0.01 -0.11 -0.125 0 0 0</pose>
        <geometry>
          <box>
            <size>0.07 0.02 0.25</size>
          </box>
        </geometry>
      </collision>
      <collision name='fr_hipy_collision_1'>
        <pose>0 -0.11 -0.25 1.57079632 0 0</pose>
        <geometry>
          <cylinder>
            <length>0.089999999999999997</length>
            <radius>0.050000000000000003</radius>
          </cylinder>
        </geometry>
      </collision>
      <visual name='fr_hipy_visual'>
        <pose>0 0 0 0 0 0</pose>
        <geometry>
          <mesh>
            <scale>1 1 1</scale>
            <uri>../meshes/fr_hipy.STL</uri>
          </mesh>
        </geometry>
        <material>
          <diffuse>0.941176 0.941176 0.941176 1</diffuse>
          <ambient>0.941176 0.941176 0.941176 1</ambient>
        </material>
      </visual>
    </link>
    <joint name='fr_knee_joint' type='revolute'>
      <pose relative_to='fr_hipy'>0 -0.0984 -0.25 0 0 0</pose>
      <parent>fr_hipy</parent>
      <child>fr_knee</child>
      <axis>
        <xyz>0 -1 0</xyz>
        <limit>
          <lower>-2.7919999999999998</lower>
          <upper>2.8090000000000002</upper>
          <effort>76.400000000000006</effort>
          <velocity>22.399999999999999</velocity>
        </limit>
        <dynamics>
          <spring_reference>0</spring_reference>
          <spring_stiffness>0</spring_stiffness>
        </dynamics>
      </axis>
    </joint>
    <link name='fr_knee'>
      <pose relative_to='fr_knee_joint'>0 0 0 0 0 0</pose>
      <inertial>
        <pose>0.0035494546955584 -0.002478843181213 -0.180089236444296 0 0 0</pose>
        <mass>1.26</mass>
        <inertia>
          <ixx>0.012936</ixx>
          <ixy>5.3000000000000001e-05</ixy>
          <ixz>0.00022599999999999999</ixz>
          <iyy>0.013122999999999999</iyy>
          <iyz>0.001681</iyz>
          <izz>0.0012830000000000001</izz>
        </inertia>
      </inertial>
      <collision name='fr_knee_collision'>
        <pose>0.015 0.015 -0.125 0 0 0</pose>
        <geometry>
          <box>
            <size>0.06 0.025 0.25</size>
          </box>
        </geometry>
      </collision>
      <collision name='fr_knee_collision_1'>
        <pose>0 -0.02 -0.25 1.57079632 0 0</pose>
        <geometry>
          <cylinder>
            <length>0.10000000000000001</length>
            <radius>0.040000000000000001</radius>
          </cylinder>
        </geometry>
      </collision>
      <visual name='fr_knee_visual'>
        <pose>0 0 0 0 0 0</pose>
        <geometry>
          <mesh>
            <scale>1 1 1</scale>
            <uri>../meshes/fr_knee.STL</uri>
          </mesh>
        </geometry>
        <material>
          <diffuse>0.941176 0.941176 0.941176 1</diffuse>
          <ambient>0.941176 0.941176 0.941176 1</ambient>
        </material>
      </visual>
    </link>
    <joint name='fr_wheel_joint' type='revolute'>
      <pose relative_to='fr_knee'>0 -0.059676 -0.25 0 0 0</pose>
      <parent>fr_knee</parent>
      <child>fr_wheel</child>
      <axis>
        <xyz>0 -1 0</xyz>
        <limit>
          <effort>21.600000000000001</effort>
          <velocity>79.299999999999997</velocity>
          <lower>-10000000000000000</lower>
          <upper>10000000000000000</upper>
        </limit>
        <dynamics>
          <spring_reference>0</spring_reference>
          <spring_stiffness>0</spring_stiffness>
        </dynamics>
      </axis>
    </joint>
    <link name='fr_wheel'>
      <pose relative_to='fr_wheel_joint'>0 0 0 0 0 0</pose>
      <inertial>
        <pose>-6.4732687427016e-07 -0.000279012463466427 -4.62420470803693e-08 0 0 0</pose>
        <mass>0.63800000000000001</mass>
        <inertia>
          <ixx>0.0015349999999999999</ixx>
          <ixy>0</ixy>
          <ixz>0</ixz>
          <iyy>0.0028530000000000001</iyy>
          <iyz>0</iyz>
          <izz>0.0015349999999999999</izz>
        </inertia>
      </inertial>
      <collision name='fr_wheel_collision'>
        <pose>0 0 0 1.57079632 0 0</pose>
        <geometry>
          <cylinder>
            <length>0.053999999999999999</length>
            <radius>0.089999999999999997</radius>
          </cylinder>
        </geometry>
        <surface>
          <friction>
            <ode>
              <mu>1.0</mu>
              <mu2>1.0</mu2>
              <fdir1>0 0 1</fdir1>
            </ode>
          </friction>
          <contact>
            <ode>
              <kp>1e6</kp>
              <kd>100</kd>
              <min_depth>0.001</min_depth>
            </ode>
          </contact>
        </surface>
      </collision>
      <visual name='fr_wheel_visual'>
        <pose>0 0 0 0 0 0</pose>
        <geometry>
          <mesh>
            <scale>1 1 1</scale>
            <uri>../meshes/fr_wheel.STL</uri>
          </mesh>
        </geometry>
        <material>
          <diffuse>0.941176 0.941176 0.941176 1</diffuse>
          <ambient>0.941176 0.941176 0.941176 1</ambient>
        </material>
      </visual>
    </link>
    <joint name='hl_hipx_joint' type='revolute'>
      <pose relative_to='base_link'>-0.3141 0.06850000000000001 0 0 0 0</pose>
      <parent>base_link</parent>
      <child>hl_hipx</child>
      <axis>
        <xyz>-1 0 0</xyz>
        <limit>
          <lower>-0.61099999999999999</lower>
          <upper>0.436</upper>
          <effort>76.400000000000006</effort>
          <velocity>22.399999999999999</velocity>
        </limit>
        <dynamics>
          <spring_reference>0</spring_reference>
          <spring_stiffness>0</spring_stiffness>
        </dynamics>
      </axis>
    </joint>
    <link name='hl_hipx'>
      <pose relative_to='hl_hipx_joint'>0 0 0 0 0 0</pose>
      <inertial>
        <pose>0.0110900940233134 0.008750140350407431 0.000524883746291591 0 0 0</pose>
        <mass>0.261359958476582</mass>
        <inertia>
          <ixx>0.00018599999999999999</ixx>
          <ixy>-2.5000000000000001e-05</ixy>
          <ixz>1.2e-05</ixz>
          <iyy>0.00037100000000000002</iyy>
          <iyz>-7.9999999999999996e-06</iyz>
          <izz>0.00028800000000000001</izz>
        </inertia>
      </inertial>
      <collision name='hl_hipx_collision'>
        <pose>0 0.055 0 1.57079632 0 0</pose>
        <geometry>
          <cylinder>
            <length>0.14000000000000001</length>
            <radius>0.048000000000000001</radius>
          </cylinder>
        </geometry>
      </collision>
      <visual name='hl_hipx_visual'>
        <pose>0 0 0 0 0 0</pose>
        <geometry>
          <mesh>
            <scale>1 1 1</scale>
            <uri>../meshes/hl_hipx.STL</uri>
          </mesh>
        </geometry>
        <material>
          <diffuse>0.941176 0.941176 0.941176 1</diffuse>
          <ambient>0.941176 0.941176 0.941176 1</ambient>
        </material>
      </visual>
    </link>
    <joint name='hl_hipy_joint' type='revolute'>
      <pose relative_to='hl_hipx'>0 0 0 0 0 0</pose>
      <parent>hl_hipx</parent>
      <child>hl_hipy</child>
      <axis>
        <xyz>0 -1 0</xyz>
        <limit>
          <lower>-2.286</lower>
          <upper>2.5830000000000002</upper>
          <effort>76.400000000000006</effort>
          <velocity>22.399999999999999</velocity>
        </limit>
        <dynamics>
          <spring_reference>0</spring_reference>
          <spring_stiffness>0</spring_stiffness>
        </dynamics>
      </axis>
    </joint>
    <link name='hl_hipy'>
      <pose relative_to='hl_hipy_joint'>0 0 0 0 0 0</pose>
      <inertial>
        <pose>0.00204343366218146 0.09902274738330449 -0.13069726691312 0 0 0</pose>
        <mass>2.4929999999999999</mass>
        <inertia>
          <ixx>0.039361</ixx>
          <ixy>2.9e-05</ixy>
          <ixz>9.0000000000000002e-06</ixz>
          <iyy>0.038553999999999998</iyy>
          <iyz>-0.0060010000000000003</iyz>
          <izz>0.0039139999999999999</izz>
        </inertia>
      </inertial>
      <collision name='hl_hipy_collision'>
        <pose>0.01 0.11 -0.125 0 0 0</pose>
        <geometry>
          <box>
            <size>0.07 0.02 0.25</size>
          </box>
        </geometry>
      </collision>
      <collision name='hl_hipy_collision_1'>
        <pose>0 0.11 -0.25 1.57079632 0 0</pose>
        <geometry>
          <cylinder>
            <length>0.089999999999999997</length>
            <radius>0.050000000000000003</radius>
          </cylinder>
        </geometry>
      </collision>
      <visual name='hl_hipy_visual'>
        <pose>0 0 0 0 0 0</pose>
        <geometry>
          <mesh>
            <scale>1 1 1</scale>
            <uri>../meshes/hl_hipy.STL</uri>
          </mesh>
        </geometry>
        <material>
          <diffuse>0.941176 0.941176 0.941176 1</diffuse>
          <ambient>0.941176 0.941176 0.941176 1</ambient>
        </material>
      </visual>
    </link>
    <joint name='hl_knee_joint' type='revolute'>
      <pose relative_to='hl_hipy'>0 0.0984 -0.25 0 0 0</pose>
      <parent>hl_hipy</parent>
      <child>hl_knee</child>
      <axis>
        <xyz>0 -1 0</xyz>
        <limit>
          <lower>-2.8090000000000002</lower>
          <upper>2.7919999999999998</upper>
          <effort>76.400000000000006</effort>
          <velocity>22.399999999999999</velocity>
        </limit>
        <dynamics>
          <spring_reference>0</spring_reference>
          <spring_stiffness>0</spring_stiffness>
        </dynamics>
      </axis>
    </joint>
    <link name='hl_knee'>
      <pose relative_to='hl_knee_joint'>0 0 0 0 0 0</pose>
      <inertial>
        <pose>-0.00354945209738589 0.00247884637205834 -0.180089257150601 0 0 0</pose>
        <mass>1.26</mass>
        <inertia>
          <ixx>0.012936</ixx>
          <ixy>5.3000000000000001e-05</ixy>
          <ixz>-0.00022599999999999999</ixz>
          <iyy>0.013122999999999999</iyy>
          <iyz>-0.001681</iyz>
          <izz>0.0012830000000000001</izz>
        </inertia>
      </inertial>
      <collision name='hl_knee_collision'>
        <pose>-0.015 0.015 -0.125 0 0 0</pose>
        <geometry>
          <box>
            <size>0.06 0.025 0.25</size>
          </box>
        </geometry>
      </collision>
      <collision name='hl_knee_collision_1'>
        <pose>0 0.02 -0.25 1.57079632 0 0</pose>
        <geometry>
          <cylinder>
            <length>0.10000000000000001</length>
            <radius>0.040000000000000001</radius>
          </cylinder>
        </geometry>
      </collision>
      <visual name='hl_knee_visual'>
        <pose>0 0 0 0 0 0</pose>
        <geometry>
          <mesh>
            <scale>1 1 1</scale>
            <uri>../meshes/hl_knee.STL</uri>
          </mesh>
        </geometry>
        <material>
          <diffuse>0.941176 0.941176 0.941176 1</diffuse>
          <ambient>0.941176 0.941176 0.941176 1</ambient>
        </material>
      </visual>
    </link>
    <joint name='hl_wheel_joint' type='revolute'>
      <pose relative_to='hl_knee'>0 0.059676 -0.25 0 0 0</pose>
      <parent>hl_knee</parent>
      <child>hl_wheel</child>
      <axis>
        <xyz>0 -1 0</xyz>
        <limit>
          <effort>21.600000000000001</effort>
          <velocity>79.299999999999997</velocity>
          <lower>-10000000000000000</lower>
          <upper>10000000000000000</upper>
        </limit>
        <dynamics>
          <spring_reference>0</spring_reference>
          <spring_stiffness>0</spring_stiffness>
        </dynamics>
      </axis>
    </joint>
    <link name='hl_wheel'>
      <pose relative_to='hl_wheel_joint'>0 0 0 0 0 0</pose>
      <inertial>
        <pose>-6.07889369508285e-07 0.000279009097070765 2.10489879304276e-07 0 0 0</pose>
        <mass>0.63800000000000001</mass>
        <inertia>
          <ixx>0.0015349999999999999</ixx>
          <ixy>0</ixy>
          <ixz>0</ixz>
          <iyy>0.0028530000000000001</iyy>
          <iyz>0</iyz>
          <izz>0.0015349999999999999</izz>
        </inertia>
      </inertial>
      <collision name='hl_wheel_collision'>
        <pose>0 0 0 1.57079632 0 0</pose>
        <geometry>
          <cylinder>
            <length>0.053999999999999999</length>
            <radius>0.089999999999999997</radius>
          </cylinder>
        </geometry>
        <surface>
          <friction>
            <ode>
              <mu>1.0</mu>
              <mu2>1.0</mu2>
              <fdir1>0 0 1</fdir1>
            </ode>
          </friction>
          <contact>
            <ode>
              <kp>1e6</kp>
              <kd>100</kd>
              <min_depth>0.001</min_depth>
            </ode>
          </contact>
        </surface>
      </collision>
      <visual name='hl_wheel_visual'>
        <pose>0 0 0 0 0 0</pose>
        <geometry>
          <mesh>
            <scale>1 1 1</scale>
            <uri>../meshes/hl_wheel.STL</uri>
          </mesh>
        </geometry>
        <material>
          <diffuse>0.941176 0.941176 0.941176 1</diffuse>
          <ambient>0.941176 0.941176 0.941176 1</ambient>
        </material>
      </visual>
    </link>
    <joint name='hr_hipx_joint' type='revolute'>
      <pose relative_to='base_link'>-0.3141 -0.06850000000000001 0 0 0 0</pose>
      <parent>base_link</parent>
      <child>hr_hipx</child>
      <axis>
        <xyz>-1 0 0</xyz>
        <limit>
          <lower>-0.436</lower>
          <upper>0.61099999999999999</upper>
          <effort>76.400000000000006</effort>
          <velocity>22.399999999999999</velocity>
        </limit>
        <dynamics>
          <spring_reference>0</spring_reference>
          <spring_stiffness>0</spring_stiffness>
        </dynamics>
      </axis>
    </joint>
    <link name='hr_hipx'>
      <pose relative_to='hr_hipx_joint'>0 0 0 0 0 0</pose>
      <inertial>
        <pose>0.0110901558226165 -0.00875011717083631 0.000524936954718227 0 0 0</pose>
        <mass>0.261359958476582</mass>
        <inertia>
          <ixx>0.00018599999999999999</ixx>
          <ixy>2.5000000000000001e-05</ixy>
          <ixz>1.2e-05</ixz>
          <iyy>0.00037100000000000002</iyy>
          <iyz>7.9999999999999996e-06</iyz>
          <izz>0.00028800000000000001</izz>
        </inertia>
      </inertial>
      <collision name='hr_hipx_collision'>
        <pose>0 -0.055 0 1.57079632 0 0</pose>
        <geometry>
          <cylinder>
            <length>0.14000000000000001</length>
            <radius>0.048000000000000001</radius>
          </cylinder>
        </geometry>
      </collision>
      <visual name='hr_hipx_visual'>
        <pose>0 0 0 0 0 0</pose>
        <geometry>
          <mesh>
            <scale>1 1 1</scale>
            <uri>../meshes/hr_hipx.STL</uri>
          </mesh>
        </geometry>
        <material>
          <diffuse>0.941176 0.941176 0.941176 1</diffuse>
          <ambient>0.941176 0.941176 0.941176 1</ambient>
        </material>
      </visual>
    </link>
    <joint name='hr_hipy_joint' type='revolute'>
      <pose relative_to='hr_hipx'>0 0 0 0 0 0</pose>
      <parent>hr_hipx</parent>
      <child>hr_hipy</child>
      <axis>
        <xyz>0 -1 0</xyz>
        <limit>
          <lower>-2.286</lower>
          <upper>2.5830000000000002</upper>
          <effort>76.400000000000006</effort>
          <velocity>22.399999999999999</velocity>
        </limit>
        <dynamics>
          <spring_reference>0</spring_reference>
          <spring_stiffness>0</spring_stiffness>
        </dynamics>
      </axis>
    </joint>
    <link name='hr_hipy'>
      <pose relative_to='hr_hipy_joint'>0 0 0 0 0 0</pose>
      <inertial>
        <pose>0.00199199678434109 -0.0983704174694303 -0.13056065751366 0 0 0</pose>
        <mass>2.4929999999999999</mass>
        <inertia>
          <ixx>0.038878000000000003</ixx>
          <ixy>-2.1999999999999999e-05</ixy>
          <ixz>3.4e-05</ixz>
          <iyy>0.038052999999999997</iyy>
          <iyz>0.0059950000000000003</iyz>
          <izz>0.0038539999999999998</izz>
        </inertia>
      </inertial>
      <collision name='hr_hipy_collision'>
        <pose>0.01 -0.11 -0.125 0 0 0</pose>
        <geometry>
          <box>
            <size>0.07 0.02 0.25</size>
          </box>
        </geometry>
      </collision>
      <collision name='hr_hipy_collision_1'>
        <pose>0 -0.11 -0.25 1.57079632 0 0</pose>
        <geometry>
          <cylinder>
            <length>0.089999999999999997</length>
            <radius>0.050000000000000003</radius>
          </cylinder>
        </geometry>
      </collision>
      <visual name='hr_hipy_visual'>
        <pose>0 0 0 0 0 0</pose>
        <geometry>
          <mesh>
            <scale>1 1 1</scale>
            <uri>../meshes/hr_hipy.STL</uri>
          </mesh>
        </geometry>
        <material>
          <diffuse>0.941176 0.941176 0.941176 1</diffuse>
          <ambient>0.941176 0.941176 0.941176 1</ambient>
        </material>
      </visual>
    </link>
    <joint name='hr_knee_joint' type='revolute'>
      <pose relative_to='hr_hipy'>0 -0.0984 -0.25 0 0 0</pose>
      <parent>hr_hipy</parent>
      <child>hr_knee</child>
      <axis>
        <xyz>0 -1 0</xyz>
        <limit>
          <lower>-2.8090000000000002</lower>
          <upper>2.7919999999999998</upper>
          <effort>76.400000000000006</effort>
          <velocity>22.399999999999999</velocity>
        </limit>
        <dynamics>
          <spring_reference>0</spring_reference>
          <spring_stiffness>0</spring_stiffness>
        </dynamics>
      </axis>
    </joint>
    <link name='hr_knee'>
      <pose relative_to='hr_knee_joint'>0 0 0 0 0 0</pose>
      <inertial>
        <pose>-0.00341053036115846 -0.0027020185369851 -0.181287492263963 0 0 0</pose>
        <mass>1.26</mass>
        <inertia>
          <ixx>0.012936</ixx>
          <ixy>-5.3000000000000001e-05</ixy>
          <ixz>-0.00022599999999999999</ixz>
          <iyy>0.013122999999999999</iyy>
          <iyz>0.001681</iyz>
          <izz>0.0012830000000000001</izz>
        </inertia>
      </inertial>
      <collision name='hr_knee_collision'>
        <pose>-0.015 0.015 -0.125 0 0 0</pose>
        <geometry>
          <box>
            <size>0.06 0.025 0.25</size>
          </box>
        </geometry>
      </collision>
      <collision name='hr_knee_collision_1'>
        <pose>0 -0.02 -0.25 1.57079632 0 0</pose>
        <geometry>
          <cylinder>
            <length>0.10000000000000001</length>
            <radius>0.040000000000000001</radius>
          </cylinder>
        </geometry>
      </collision>
      <visual name='hr_knee_visual'>
        <pose>0 0 0 0 0 0</pose>
        <geometry>
          <mesh>
            <scale>1 1 1</scale>
            <uri>../meshes/hr_knee.STL</uri>
          </mesh>
        </geometry>
        <material>
          <diffuse>0.941176 0.941176 0.941176 1</diffuse>
          <ambient>0.941176 0.941176 0.941176 1</ambient>
        </material>
      </visual>
    </link>
    <joint name='hr_wheel_joint' type='revolute'>
      <pose relative_to='hr_knee'>0 -0.059676 -0.25 0 0 0</pose>
      <parent>hr_knee</parent>
      <child>hr_wheel</child>
      <axis>
        <xyz>0 -1 0</xyz>
        <limit>
          <effort>21.600000000000001</effort>
          <velocity>79.299999999999997</velocity>
          <lower>-10000000000000000</lower>
          <upper>10000000000000000</upper>
        </limit>
        <dynamics>
          <spring_reference>0</spring_reference>
          <spring_stiffness>0</spring_stiffness>
        </dynamics>
      </axis>
    </joint>
    <link name='hr_wheel'>
      <pose relative_to='hr_wheel_joint'>0 0 0 0 0 0</pose>
      <inertial>
        <pose>6.09746291457824e-07 -0.00027900886004309 2.0131377032051e-07 0 0 0</pose>
        <mass>0.63800000000000001</mass>
        <inertia>
          <ixx>0.0015349999999999999</ixx>
          <ixy>0</ixy>
          <ixz>0</ixz>
          <iyy>0.0028530000000000001</iyy>
          <iyz>0</iyz>
          <izz>0.0015349999999999999</izz>
        </inertia>
      </inertial>
      <collision name='hr_wheel_collision'>
        <pose>0 0 0 1.57079632 0 0</pose>
        <geometry>
          <cylinder>
            <length>0.053999999999999999</length>
            <radius>0.089999999999999997</radius>
          </cylinder>
        </geometry>
        <surface>
          <friction>
            <ode>
              <mu>1.0</mu>
              <mu2>1.0</mu2>
              <fdir1>0 0 1</fdir1>
            </ode>
          </friction>
          <contact>
            <ode>
              <kp>1e6</kp>
              <kd>100</kd>
              <min_depth>0.001</min_depth>
            </ode>
          </contact>
        </surface>
      </collision>
      <visual name='hr_wheel_visual'>
        <pose>0 0 0 0 0 0</pose>
        <geometry>
          <mesh>
            <scale>1 1 1</scale>
            <uri>../meshes/hr_wheel.STL</uri>
          </mesh>
        </geometry>
        <material>
          <diffuse>0.941176 0.941176 0.941176 1</diffuse>
          <ambient>0.941176 0.941176 0.941176 1</ambient>
        </material>
      </visual>
    </link>
    
    <!-- ===== PLUGINS ===== -->
    
    <!-- Contact Plugin for collision detection -->
    <plugin filename="ignition-gazebo-contact-system" name="gz::sim::systems::Contact"/>
    
    <!-- IMU Sensor Plugin -->
    <plugin filename="ignition-gazebo-imu-system" name="gz::sim::systems::Imu"/>
    
    <!-- Joint State Publisher Plugin -->
    <plugin filename="ignition-gazebo-joint-state-publisher-system" name="gz::sim::systems::JointStatePublisher">
      <joint_name>fl_hipx_joint</joint_name>
      <joint_name>fl_hipy_joint</joint_name>
      <joint_name>fl_knee_joint</joint_name>
      <joint_name>fl_wheel_joint</joint_name>
      <joint_name>fr_hipx_joint</joint_name>
      <joint_name>fr_hipy_joint</joint_name>
      <joint_name>fr_knee_joint</joint_name>
      <joint_name>fr_wheel_joint</joint_name>
      <joint_name>hl_hipx_joint</joint_name>
      <joint_name>hl_hipy_joint</joint_name>
      <joint_name>hl_knee_joint</joint_name>
      <joint_name>hl_wheel_joint</joint_name>
      <joint_name>hr_hipx_joint</joint_name>
      <joint_name>hr_hipy_joint</joint_name>
      <joint_name>hr_knee_joint</joint_name>
      <joint_name>hr_wheel_joint</joint_name>
    </plugin>
    
    <!-- Apply Joint Force Plugin for each joint -->
    <plugin filename="ignition-gazebo-apply-joint-force-system" name="gz::sim::systems::ApplyJointForce">
      <joint_name>fl_hipx_joint</joint_name>
    </plugin>
    <plugin filename="ignition-gazebo-apply-joint-force-system" name="gz::sim::systems::ApplyJointForce">
      <joint_name>fl_hipy_joint</joint_name>
    </plugin>
    <plugin filename="ignition-gazebo-apply-joint-force-system" name="gz::sim::systems::ApplyJointForce">
      <joint_name>fl_knee_joint</joint_name>
    </plugin>
    <plugin filename="ignition-gazebo-apply-joint-force-system" name="gz::sim::systems::ApplyJointForce">
      <joint_name>fl_wheel_joint</joint_name>
    </plugin>
    <plugin filename="ignition-gazebo-apply-joint-force-system" name="gz::sim::systems::ApplyJointForce">
      <joint_name>fr_hipx_joint</joint_name>
    </plugin>
    <plugin filename="ignition-gazebo-apply-joint-force-system" name="gz::sim::systems::ApplyJointForce">
      <joint_name>fr_hipy_joint</joint_name>
    </plugin>
    <plugin filename="ignition-gazebo-apply-joint-force-system" name="gz::sim::systems::ApplyJointForce">
      <joint_name>fr_knee_joint</joint_name>
    </plugin>
    <plugin filename="ignition-gazebo-apply-joint-force-system" name="gz::sim::systems::ApplyJointForce">
      <joint_name>fr_wheel_joint</joint_name>
    </plugin>
    <plugin filename="ignition-gazebo-apply-joint-force-system" name="gz::sim::systems::ApplyJointForce">
      <joint_name>hl_hipx_joint</joint_name>
    </plugin>
    <plugin filename="ignition-gazebo-apply-joint-force-system" name="gz::sim::systems::ApplyJointForce">
      <joint_name>hl_hipy_joint</joint_name>
    </plugin>
    <plugin filename="ignition-gazebo-apply-joint-force-system" name="gz::sim::systems::ApplyJointForce">
      <joint_name>hl_knee_joint</joint_name>
    </plugin>
    <plugin filename="ignition-gazebo-apply-joint-force-system" name="gz::sim::systems::ApplyJointForce">
      <joint_name>hl_wheel_joint</joint_name>
    </plugin>
    <plugin filename="ignition-gazebo-apply-joint-force-system" name="gz::sim::systems::ApplyJointForce">
      <joint_name>hr_hipx_joint</joint_name>
    </plugin>
    <plugin filename="ignition-gazebo-apply-joint-force-system" name="gz::sim::systems::ApplyJointForce">
      <joint_name>hr_hipy_joint</joint_name>
    </plugin>
    <plugin filename="ignition-gazebo-apply-joint-force-system" name="gz::sim::systems::ApplyJointForce">
      <joint_name>hr_knee_joint</joint_name>
    </plugin>
    <plugin filename="ignition-gazebo-apply-joint-force-system" name="gz::sim::systems::ApplyJointForce">
      <joint_name>hr_wheel_joint</joint_name>
    </plugin>
    
  </model>
</sdf>
